scripts/customTests/16.in
#basic-exec-reject-cancel
40
0-39 o
0 B 1 AAPL 2705 4
0 S 2 AAPL 2705 12
0 C 1
0 B 3 MSFT 2705 4
0 S 4 MSFT 2705 12
0 C 3
1 B 5 AAPL 2705 4
1 S 6 AAPL 2705 12
1 C 5
1 B 7 MSFT 2705 4
1 S 8 MSFT 2705 12
1 C 7
2 B 9 AAPL 2705 4
2 S 10 AAPL 2705 12
2 C 9
2 B 11 MSFT 2705 4
2 S 12 MSFT 2705 12
2 C 11
3 B 13 AAPL 2705 4
3 S 14 AAPL 2705 12
3 C 13
3 B 15 MSFT 2705 4
3 S 16 MSFT 2705 12
3 C 15
4 B 17 AAPL 2705 4
4 S 18 AAPL 2705 12
4 C 17
4 B 19 MSFT 2705 4
4 S 20 MSFT 2705 12
4 C 19
5 B 21 AAPL 2705 4
5 S 22 AAPL 2705 12
5 C 21
5 B 23 MSFT 2705 4
5 S 24 MSFT 2705 12
5 C 23
6 B 25 AAPL 2705 4
6 S 26 AAPL 2705 12
6 C 25
6 B 27 MSFT 2705 4
6 S 28 MSFT 2705 12
6 C 27
7 B 29 AAPL 2705 4
7 S 30 AAPL 2705 12
7 C 29
7 B 31 MSFT 2705 4
7 S 32 MSFT 2705 12
7 C 31
8 B 33 AAPL 2705 4
8 S 34 AAPL 2705 12
8 C 33
8 B 35 MSFT 2705 4
8 S 36 MSFT 2705 12
8 C 35
9 B 37 AAPL 2705 4
9 S 38 AAPL 2705 12
9 C 37
9 B 39 MSFT 2705 4
9 S 40 MSFT 2705 12
9 C 39
10 B 41 AAPL 2705 4
10 S 42 AAPL 2705 12
10 C 41
10 B 43 MSFT 2705 4
10 S 44 MSFT 2705 12
10 C 43
11 B 45 AAPL 2705 4
11 S 46 AAPL 2705 12
11 C 45
11 B 47 MSFT 2705 4
11 S 48 MSFT 2705 12
11 C 47
12 B 49 AAPL 2705 4
12 S 50 AAPL 2705 12
12 C 49
12 B 51 MSFT 2705 4
12 S 52 MSFT 2705 12
12 C 51
13 B 53 AAPL 2705 4
13 S 54 AAPL 2705 12
13 C 53
13 B 55 MSFT 2705 4
13 S 56 MSFT 2705 12
13 C 55
14 B 57 AAPL 2705 4
14 S 58 AAPL 2705 12
14 C 57
14 B 59 MSFT 2705 4
14 S 60 MSFT 2705 12
14 C 59
15 B 61 AAPL 2705 4
15 S 62 AAPL 2705 12
15 C 61
15 B 63 MSFT 2705 4
15 S 64 MSFT 2705 12
15 C 63
16 B 65 AAPL 2705 4
16 S 66 AAPL 2705 12
16 C 65
16 B 67 MSFT 2705 4
16 S 68 MSFT 2705 12
16 C 67
17 B 69 AAPL 2705 4
17 S 70 AAPL 2705 12
17 C 69
17 B 71 MSFT 2705 4
17 S 72 MSFT 2705 12
17 C 71
18 B 73 AAPL 2705 4
18 S 74 AAPL 2705 12
18 C 73
18 B 75 MSFT 2705 4
18 S 76 MSFT 2705 12
18 C 75
19 B 77 AAPL 2705 4
19 S 78 AAPL 2705 12
19 C 77
19 B 79 MSFT 2705 4
19 S 80 MSFT 2705 12
19 C 79
20 B 81 AAPL 2705 4
20 S 82 AAPL 2705 12
20 C 81
20 B 83 MSFT 2705 4
20 S 84 MSFT 2705 12
20 C 83
21 B 85 AAPL 2705 4
21 S 86 AAPL 2705 12
21 C 85
21 B 87 MSFT 2705 4
21 S 88 MSFT 2705 12
21 C 87
22 B 89 AAPL 2705 4
22 S 90 AAPL 2705 12
22 C 89
22 B 91 MSFT 2705 4
22 S 92 MSFT 2705 12
22 C 91
23 B 93 AAPL 2705 4
23 S 94 AAPL 2705 12
23 C 93
23 B 95 MSFT 2705 4
23 S 96 MSFT 2705 12
23 C 95
24 B 97 AAPL 2705 4
24 S 98 AAPL 2705 12
24 C 97
24 B 99 MSFT 2705 4
24 S 100 MSFT 2705 12
24 C 99
25 B 101 AAPL 2705 4
25 S 102 AAPL 2705 12
25 C 101
25 B 103 MSFT 2705 4
25 S 104 MSFT 2705 12
25 C 103
26 B 105 AAPL 2705 4
26 S 106 AAPL 2705 12
26 C 105
26 B 107 MSFT 2705 4
26 S 108 MSFT 2705 12
26 C 107
27 B 109 AAPL 2705 4
27 S 110 AAPL 2705 12
27 C 109
27 B 111 MSFT 2705 4
27 S 112 MSFT 2705 12
27 C 111
28 B 113 AAPL 2705 4
28 S 114 AAPL 2705 12
28 C 113
28 B 115 MSFT 2705 4
28 S 116 MSFT 2705 12
28 C 115
29 B 117 AAPL 2705 4
29 S 118 AAPL 2705 12
29 C 117
29 B 119 MSFT 2705 4
29 S 120 MSFT 2705 12
29 C 119
30 B 121 AAPL 2705 4
30 S 122 AAPL 2705 12
30 C 121
30 B 123 MSFT 2705 4
30 S 124 MSFT 2705 12
30 C 123
31 B 125 AAPL 2705 4
31 S 126 AAPL 2705 12
31 C 125
31 B 127 MSFT 2705 4
31 S 128 MSFT 2705 12
31 C 127
32 B 129 AAPL 2705 4
32 S 130 AAPL 2705 12
32 C 129
32 B 131 MSFT 2705 4
32 S 132 MSFT 2705 12
32 C 131
33 B 133 AAPL 2705 4
33 S 134 AAPL 2705 12
33 C 133
33 B 135 MSFT 2705 4
33 S 136 MSFT 2705 12
33 C 135
34 B 137 AAPL 2705 4
34 S 138 AAPL 2705 12
34 C 137
34 B 139 MSFT 2705 4
34 S 140 MSFT 2705 12
34 C 139
35 B 141 AAPL 2705 4
35 S 142 AAPL 2705 12
35 C 141
35 B 143 MSFT 2705 4
35 S 144 MSFT 2705 12
35 C 143
36 B 145 AAPL 2705 4
36 S 146 AAPL 2705 12
36 C 145
36 B 147 MSFT 2705 4
36 S 148 MSFT 2705 12
36 C 147
37 B 149 AAPL 2705 4
37 S 150 AAPL 2705 12
37 C 149
37 B 151 MSFT 2705 4
37 S 152 MSFT 2705 12
37 C 151
38 B 153 AAPL 2705 4
38 S 154 AAPL 2705 12
38 C 153
38 B 155 MSFT 2705 4
38 S 156 MSFT 2705 12
38 C 155
39 B 157 AAPL 2705 4
39 S 158 AAPL 2705 12
39 C 157
39 B 159 MSFT 2705 4
39 S 160 MSFT 2705 12
39 C 159
.
0-39 x
