scripts/customTests/17.in
#basic-multiple-exec
40
0-39 o
0 B 1 AAPL 2705 24
0 B 2 AAPL 2705 13
0 S 3 AAPL 2705 30
0 S 4 AAPL 2705 18
0 B 5 MSFT 2705 24
0 B 6 MSFT 2705 13
0 S 7 MSFT 2705 30
0 S 8 MSFT 2705 18
1 B 9 AAPL 2705 24
1 B 10 AAPL 2705 13
1 S 11 AAPL 2705 30
1 S 12 AAPL 2705 18
1 B 13 MSFT 2705 24
1 B 14 MSFT 2705 13
1 S 15 MSFT 2705 30
1 S 16 MSFT 2705 18
2 B 17 AAPL 2705 24
2 B 18 AAPL 2705 13
2 S 19 AAPL 2705 30
2 S 20 AAPL 2705 18
2 B 21 MSFT 2705 24
2 B 22 MSFT 2705 13
2 S 23 MSFT 2705 30
2 S 24 MSFT 2705 18
3 B 25 AAPL 2705 24
3 B 26 AAPL 2705 13
3 S 27 AAPL 2705 30
3 S 28 AAPL 2705 18
3 B 29 MSFT 2705 24
3 B 30 MSFT 2705 13
3 S 31 MSFT 2705 30
3 S 32 MSFT 2705 18
4 B 33 AAPL 2705 24
4 B 34 AAPL 2705 13
4 S 35 AAPL 2705 30
4 S 36 AAPL 2705 18
4 B 37 MSFT 2705 24
4 B 38 MSFT 2705 13
4 S 39 MSFT 2705 30
4 S 40 MSFT 2705 18
5 B 41 AAPL 2705 24
5 B 42 AAPL 2705 13
5 S 43 AAPL 2705 30
5 S 44 AAPL 2705 18
5 B 45 MSFT 2705 24
5 B 46 MSFT 2705 13
5 S 47 MSFT 2705 30
5 S 48 MSFT 2705 18
6 B 49 AAPL 2705 24
6 B 50 AAPL 2705 13
6 S 51 AAPL 2705 30
6 S 52 AAPL 2705 18
6 B 53 MSFT 2705 24
6 B 54 MSFT 2705 13
6 S 55 MSFT 2705 30
6 S 56 MSFT 2705 18
7 B 57 AAPL 2705 24
7 B 58 AAPL 2705 13
7 S 59 AAPL 2705 30
7 S 60 AAPL 2705 18
7 B 61 MSFT 2705 24
7 B 62 MSFT 2705 13
7 S 63 MSFT 2705 30
7 S 64 MSFT 2705 18
8 B 65 AAPL 2705 24
8 B 66 AAPL 2705 13
8 S 67 AAPL 2705 30
8 S 68 AAPL 2705 18
8 B 69 MSFT 2705 24
8 B 70 MSFT 2705 13
8 S 71 MSFT 2705 30
8 S 72 MSFT 2705 18
9 B 73 AAPL 2705 24
9 B 74 AAPL 2705 13
9 S 75 AAPL 2705 30
9 S 76 AAPL 2705 18
9 B 77 MSFT 2705 24
9 B 78 MSFT 2705 13
9 S 79 MSFT 2705 30
9 S 80 MSFT 2705 18
10 B 81 AAPL 2705 24
10 B 82 AAPL 2705 13
10 S 83 AAPL 2705 30
10 S 84 AAPL 2705 18
10 B 85 MSFT 2705 24
10 B 86 MSFT 2705 13
10 S 87 MSFT 2705 30
10 S 88 MSFT 2705 18
11 B 89 AAPL 2705 24
11 B 90 AAPL 2705 13
11 S 91 AAPL 2705 30
11 S 92 AAPL 2705 18
11 B 93 MSFT 2705 24
11 B 94 MSFT 2705 13
11 S 95 MSFT 2705 30
11 S 96 MSFT 2705 18
12 B 97 AAPL 2705 24
12 B 98 AAPL 2705 13
12 S 99 AAPL 2705 30
12 S 100 AAPL 2705 18
12 B 101 MSFT 2705 24
12 B 102 MSFT 2705 13
12 S 103 MSFT 2705 30
12 S 104 MSFT 2705 18
13 B 105 AAPL 2705 24
13 B 106 AAPL 2705 13
13 S 107 AAPL 2705 30
13 S 108 AAPL 2705 18
13 B 109 MSFT 2705 24
13 B 110 MSFT 2705 13
13 S 111 MSFT 2705 30
13 S 112 MSFT 2705 18
14 B 113 AAPL 2705 24
14 B 114 AAPL 2705 13
14 S 115 AAPL 2705 30
14 S 116 AAPL 2705 18
14 B 117 MSFT 2705 24
14 B 118 MSFT 2705 13
14 S 119 MSFT 2705 30
14 S 120 MSFT 2705 18
15 B 121 AAPL 2705 24
15 B 122 AAPL 2705 13
15 S 123 AAPL 2705 30
15 S 124 AAPL 2705 18
15 B 125 MSFT 2705 24
15 B 126 MSFT 2705 13
15 S 127 MSFT 2705 30
15 S 128 MSFT 2705 18
16 B 129 AAPL 2705 24
16 B 130 AAPL 2705 13
16 S 131 AAPL 2705 30
16 S 132 AAPL 2705 18
16 B 133 MSFT 2705 24
16 B 134 MSFT 2705 13
16 S 135 MSFT 2705 30
16 S 136 MSFT 2705 18
17 B 137 AAPL 2705 24
17 B 138 AAPL 2705 13
17 S 139 AAPL 2705 30
17 S 140 AAPL 2705 18
17 B 141 MSFT 2705 24
17 B 142 MSFT 2705 13
17 S 143 MSFT 2705 30
17 S 144 MSFT 2705 18
18 B 145 AAPL 2705 24
18 B 146 AAPL 2705 13
18 S 147 AAPL 2705 30
18 S 148 AAPL 2705 18
18 B 149 MSFT 2705 24
18 B 150 MSFT 2705 13
18 S 151 MSFT 2705 30
18 S 152 MSFT 2705 18
19 B 153 AAPL 2705 24
19 B 154 AAPL 2705 13
19 S 155 AAPL 2705 30
19 S 156 AAPL 2705 18
19 B 157 MSFT 2705 24
19 B 158 MSFT 2705 13
19 S 159 MSFT 2705 30
19 S 160 MSFT 2705 18
20 B 161 AAPL 2705 24
20 B 162 AAPL 2705 13
20 S 163 AAPL 2705 30
20 S 164 AAPL 2705 18
20 B 165 MSFT 2705 24
20 B 166 MSFT 2705 13
20 S 167 MSFT 2705 30
20 S 168 MSFT 2705 18
21 B 169 AAPL 2705 24
21 B 170 AAPL 2705 13
21 S 171 AAPL 2705 30
21 S 172 AAPL 2705 18
21 B 173 MSFT 2705 24
21 B 174 MSFT 2705 13
21 S 175 MSFT 2705 30
21 S 176 MSFT 2705 18
22 B 177 AAPL 2705 24
22 B 178 AAPL 2705 13
22 S 179 AAPL 2705 30
22 S 180 AAPL 2705 18
22 B 181 MSFT 2705 24
22 B 182 MSFT 2705 13
22 S 183 MSFT 2705 30
22 S 184 MSFT 2705 18
23 B 185 AAPL 2705 24
23 B 186 AAPL 2705 13
23 S 187 AAPL 2705 30
23 S 188 AAPL 2705 18
23 B 189 MSFT 2705 24
23 B 190 MSFT 2705 13
23 S 191 MSFT 2705 30
23 S 192 MSFT 2705 18
24 B 193 AAPL 2705 24
24 B 194 AAPL 2705 13
24 S 195 AAPL 2705 30
24 S 196 AAPL 2705 18
24 B 197 MSFT 2705 24
24 B 198 MSFT 2705 13
24 S 199 MSFT 2705 30
24 S 200 MSFT 2705 18
25 B 201 AAPL 2705 24
25 B 202 AAPL 2705 13
25 S 203 AAPL 2705 30
25 S 204 AAPL 2705 18
25 B 205 MSFT 2705 24
25 B 206 MSFT 2705 13
25 S 207 MSFT 2705 30
25 S 208 MSFT 2705 18
26 B 209 AAPL 2705 24
26 B 210 AAPL 2705 13
26 S 211 AAPL 2705 30
26 S 212 AAPL 2705 18
26 B 213 MSFT 2705 24
26 B 214 MSFT 2705 13
26 S 215 MSFT 2705 30
26 S 216 MSFT 2705 18
27 B 217 AAPL 2705 24
27 B 218 AAPL 2705 13
27 S 219 AAPL 2705 30
27 S 220 AAPL 2705 18
27 B 221 MSFT 2705 24
27 B 222 MSFT 2705 13
27 S 223 MSFT 2705 30
27 S 224 MSFT 2705 18
28 B 225 AAPL 2705 24
28 B 226 AAPL 2705 13
28 S 227 AAPL 2705 30
28 S 228 AAPL 2705 18
28 B 229 MSFT 2705 24
28 B 230 MSFT 2705 13
28 S 231 MSFT 2705 30
28 S 232 MSFT 2705 18
29 B 233 AAPL 2705 24
29 B 234 AAPL 2705 13
29 S 235 AAPL 2705 30
29 S 236 AAPL 2705 18
29 B 237 MSFT 2705 24
29 B 238 MSFT 2705 13
29 S 239 MSFT 2705 30
29 S 240 MSFT 2705 18
30 B 241 AAPL 2705 24
30 B 242 AAPL 2705 13
30 S 243 AAPL 2705 30
30 S 244 AAPL 2705 18
30 B 245 MSFT 2705 24
30 B 246 MSFT 2705 13
30 S 247 MSFT 2705 30
30 S 248 MSFT 2705 18
31 B 249 AAPL 2705 24
31 B 250 AAPL 2705 13
31 S 251 AAPL 2705 30
31 S 252 AAPL 2705 18
31 B 253 MSFT 2705 24
31 B 254 MSFT 2705 13
31 S 255 MSFT 2705 30
31 S 256 MSFT 2705 18
32 B 257 AAPL 2705 24
32 B 258 AAPL 2705 13
32 S 259 AAPL 2705 30
32 S 260 AAPL 2705 18
32 B 261 MSFT 2705 24
32 B 262 MSFT 2705 13
32 S 263 MSFT 2705 30
32 S 264 MSFT 2705 18
33 B 265 AAPL 2705 24
33 B 266 AAPL 2705 13
33 S 267 AAPL 2705 30
33 S 268 AAPL 2705 18
33 B 269 MSFT 2705 24
33 B 270 MSFT 2705 13
33 S 271 MSFT 2705 30
33 S 272 MSFT 2705 18
34 B 273 AAPL 2705 24
34 B 274 AAPL 2705 13
34 S 275 AAPL 2705 30
34 S 276 AAPL 2705 18
34 B 277 MSFT 2705 24
34 B 278 MSFT 2705 13
34 S 279 MSFT 2705 30
34 S 280 MSFT 2705 18
35 B 281 AAPL 2705 24
35 B 282 AAPL 2705 13
35 S 283 AAPL 2705 30
35 S 284 AAPL 2705 18
35 B 285 MSFT 2705 24
35 B 286 MSFT 2705 13
35 S 287 MSFT 2705 30
35 S 288 MSFT 2705 18
36 B 289 AAPL 2705 24
36 B 290 AAPL 2705 13
36 S 291 AAPL 2705 30
36 S 292 AAPL 2705 18
36 B 293 MSFT 2705 24
36 B 294 MSFT 2705 13
36 S 295 MSFT 2705 30
36 S 296 MSFT 2705 18
37 B 297 AAPL 2705 24
37 B 298 AAPL 2705 13
37 S 299 AAPL 2705 30
37 S 300 AAPL 2705 18
37 B 301 MSFT 2705 24
37 B 302 MSFT 2705 13
37 S 303 MSFT 2705 30
37 S 304 MSFT 2705 18
38 B 305 AAPL 2705 24
38 B 306 AAPL 2705 13
38 S 307 AAPL 2705 30
38 S 308 AAPL 2705 18
38 B 309 MSFT 2705 24
38 B 310 MSFT 2705 13
38 S 311 MSFT 2705 30
38 S 312 MSFT 2705 18
39 B 313 AAPL 2705 24
39 B 314 AAPL 2705 13
39 S 315 AAPL 2705 30
39 S 316 AAPL 2705 18
39 B 317 MSFT 2705 24
39 B 318 MSFT 2705 13
39 S 319 MSFT 2705 30
39 S 320 MSFT 2705 18
.
0-39 x
