scripts/customTests/2.in
4
0-3 o
0 B 120 GOOG 2705 30
0 B 121 GOOG 2705 30
0 C 121
0 S 122 GOOG 2700 30
1 B 123 GOOG 2705 30
1 B 124 GOOG 2705 30
1 C 124
1 S 125 GOOG 2700 30
2 B 126 GOOG 2705 30
2 B 127 GOOG 2705 30
2 C 127
2 S 128 GOOG 2700 30
3 B 129 GOOG 2705 30
3 B 130 GOOG 2705 30
3 C 130
3 S 131 GOOG 2700 30
3 S 132 GOOG 2700 30
.
0-3 x
